Workbook

Sheet batteries
A1: group | B1: subgroup | C1: variable | D1: unit | E1: 2020 | F1: 2025 | G1: 2030 | H1: 2035 | I1: 2040 | J1: 2045 | K1: 2050 | L1: Annual change | N1: Source | O1: Comment
A2: Battery | B2: Gross | C2: SoC window | D2: ratio | E2: 0.65 | F2: =1-(1-E2)*(1-$L2) -> 0.825 | G2: =1-(1-F2)*(1-$L2) -> 0.9125 | H2: =1-(1-G2)*(1-$L2) -> 0.95625 | I2: =1-(1-H2)*(1-$L2) -> 0.978125 | J2: =1-(1-I2)*(1-$L2) -> 0.9890625 | K2: =1-(1-J2)*(1-$L2) -> 0.99453125 | L2: 0.5 | N2: Truck OEM engineer (anonymous)
A3: Battery | B3: Gross | C3: Calendar lifetime | D3: years | E3: 15 | F3: =$E3+(F1-$E1)*$L3 -> 16.5 | G3: =$E3+(G1-$E1)*$L3 -> 18 | H3: =$E3+(H1-$E1)*$L3 -> 19.5 | I3: =$E3+(I1-$E1)*$L3 -> 21 | J3: =$E3+(J1-$E1)*$L3 -> 22.5 | K3: =$E3+(K1-$E1)*$L3 -> 24 | L3: 0.3 | N3: See comment.
A4: Battery | B4: Gross | C4: Cycle lifetime | D4: cycles | E4: 1500 | F4: =E4*POWER(1+$L4,5) -> 2007.3384 | G4: =F4*POWER(1+$L4,5) -> 2686.2715 | H4: =G4*POWER(1+$L4,5) -> 3594.8373 | I4: =H4*POWER(1+$L4,5) -> 4810.7032 | J4: =I4*POWER(1+$L4,5) -> 6437.8061 | K4: =J4*POWER(1+$L4,5) -> 8615.2368 | L4: 0.06 | M4: Was 5% | N4: See comment. | O4: Battery parameters and their future development were first estimated based on information from Battery University (https://batteryuniversity.com) and Wikipedia's article on Lithium-ion batteries. As parameters are in practice a chemical trade-off, the joint set of parameters was adjusted based on review by an anonymous truck manufacturer engineer and several experts in a public LinkedIn discussion (https://www.linkedin.com/posts/jakobrogstadius_please-find-problems-in-my-math-these-are-activity-6777180676291653632-jaJB/).
A5: Battery | B5: Gross | C5: Reference charging rate | D5: c | E5: 1 | F5: =E5*POWER(1+$L5,5) -> 1.2166529 | G5: =F5*POWER(1+$L5,5) -> 1.4802443 | H5: =G5*POWER(1+$L5,5) -> 1.8009435 | I5: =H5*POWER(1+$L5,5) -> 2.1911231 | J5: =I5*POWER(1+$L5,5) -> 2.6658363 | K5: =J5*POWER(1+$L5,5) -> 3.2433975 | L5: 0.04 | N5: See comment.
A6: Battery | B6: Gross | C6: Reference discharging rate | D6: c | E6: 1.5 | F6: =E6*POWER(1+$L6,5) -> 1.8249794 | G6: =F6*POWER(1+$L6,5) -> 2.2203664 | H6: =G6*POWER(1+$L6,5) -> 2.7014153 | I6: =H6*POWER(1+$L6,5) -> 3.2866847 | J6: =I6*POWER(1+$L6,5) -> 3.9987545 | K6: =J6*POWER(1+$L6,5) -> 4.8650963 | L6: 0.04 | N6: See comment.
A7: Battery | B7: Gross | C7: Max permitted charging rate | D7: c | E7: {=1.5*E5:K5} -> 1.5 | F7: 1.8249794 | G7: 2.2203664 | H7: 2.7014153 | I7: 3.2866847 | J7: 3.9987545 | K7: 4.8650963 | N7: 1.5 * ref
A8: Battery | B8: Gross | C8: Max permitted discharging rate | D8: c | E8: {=1.5*E6:K6} -> 2.25 | F8: 2.737469 | G8: 3.3305496 | H8: 4.0521229 | I8: 4.9300271 | J8: 5.9981317 | K8: 7.2976444 | N8: 1.5 * ref
A9: Battery | B9: Gross | C9: Specific energy | D9: kWh per kg | E9: 0.2 | F9: =E9*POWER(1+$L9,5) -> 0.23185481 | G9: =F9*POWER(1+$L9,5) -> 0.26878328 | H9: =G9*POWER(1+$L9,5) -> 0.31159348 | I9: =H9*POWER(1+$L9,5) -> 0.36122225 | J9: =I9*POWER(1+$L9,5) -> 0.41875559 | K9: =J9*POWER(1+$L9,5) -> 0.48545249 | L9: 0.03 | N9: See comment.
A10: Battery | B10: Gross | C10: Energy density | D10: kWh per liter | E10: 0.5 | F10: =E10*POWER(1+$L10,5) -> 0.57963704 | G10: =F10*POWER(1+$L10,5) -> 0.67195819 | H10: =G10*POWER(1+$L10,5) -> 0.77898371 | I10: =H10*POWER(1+$L10,5) -> 0.90305562 | J10: =I10*POWER(1+$L10,5) -> 1.046889 | K10: =J10*POWER(1+$L10,5) -> 1.2136312 | L10: 0.03 | N10: See comment.
A11: Battery | B11: Gross | C11: Pack cost | D11: € per kWh | E11: 270 | F11: {=(E11-M11)*POWER(1+$L11,F1:K1-E1)+M11} -> 206.13697 | G11: 159.26763 | H11: 124.87003 | I11: 99.625498 | J11: 81.098433 | K11: 67.501345 | L11: -0.06 | M11: 30 | N11: Link, S., Stephan, A., Speth, D. et al. Rapidly declining costs of truck batteries and fuel cells enable large-scale road freight electrification. Nat Energy 9, 1032–1039 (2024). https://doi.org/10.1038/s41560-024-01531-9
A12: Battery | B12: Gross | C12: Production emissions | D12: kg CO₂ per kWh | E12: 150 | F12: =E12*POWER(1+$L12,5) -> 98.862228 | G12: =F12*POWER(1+$L12,5) -> 65.158268 | H12: =G12*POWER(1+$L12,5) -> 42.944611 | I12: =H12*POWER(1+$L12,5) -> 28.303999 | J12: =I12*POWER(1+$L12,5) -> 18.654643 | K12: =J12*POWER(1+$L12,5) -> 12.294931 | L12: -0.08 | N12: Statement by Northvolt that emissions will be 25% of a Chinese competitor, claimed at 160-180. Trucks in Sweden are mostly Volvo and Scania, which will use Northvolt. Remaining emissions are from raw materials production.
A13: Battery | B13: Gross | C13: End of life definition | D13: ratio of gross | E13: 0.8 | F13: =E13*POWER(1+$L13,5) -> 0.8 | G13: =F13*POWER(1+$L13,5) -> 0.8 | H13: =G13*POWER(1+$L13,5) -> 0.8 | I13: =H13*POWER(1+$L13,5) -> 0.8 | J13: =I13*POWER(1+$L13,5) -> 0.8 | K13: =J13*POWER(1+$L13,5) -> 0.8 | L13: 0 | N13: See comment.
A14: Battery | B14: Net | C14: End of life definition | D14: ratio of net | E14: {=E13:K13} -> 0.8 | F14: 0.8 | G14: 0.8 | H14: 0.8 | I14: 0.8 | J14: 0.8 | K14: 0.8 | O14: X% of net battery capacity
A15: Battery | B15: Net | C15: Calendar lifetime | D15: years | E15: {=0.9*E3:K3/E2:K2} -> 20.769231 | F15: 18 | G15: 17.753425 | H15: 18.352941 | I15: 19.322684 | J15: 20.473934 | K15: 21.718775 | N15: Inspired by Battery University | O15: See sheet "battery SoH example" for reasoning
A16: Battery | B16: Net | C16: Cycle lifetime | D16: cycles | E16: {=E4:K8/E2:K2} -> 2307.6923 | F16: 2433.1374 | G16: 2943.8592 | H16: 3759.307 | I16: 4918.2908 | J16: 6508.9982 | K16: 8662.6104
A17: Battery | B17: Net | C17: Reference charging rate | D17: c | E17: 1.5384615 | F17: 1.4747308 | G17: 1.6221855 | H17: 1.8833396 | I17: 2.2401259 | J17: 2.6953164 | K17: 3.2612324
A18: Battery | B18: Net | C18: Reference discharging rate | D18: c | E18: 2.3076923 | F18: 2.2120962 | G18: 2.4332783 | H18: 2.8250094 | I18: 3.3601888 | J18: 4.0429745 | K18: 4.8918486
A19: Battery | B19: Net | C19: Max permitted charging rate | D19: c | E19: 2.3076923 | F19: 2.2120962 | G19: 2.4332783 | H19: 2.8250094 | I19: 3.3601888 | J19: 4.0429745 | K19: 4.8918486
A20: Battery | B20: Net | C20: Max permitted discharging rate | D20: c | E20: 3.4615385 | F20: 3.3181443 | G20: 3.6499174 | H20: 4.2375141 | I20: 5.0402833 | J20: 6.0644618 | K20: 7.3377728
A21: Battery | B21: Net | C21: Specific energy | D21: kWh per kg | E21: {=E9:K10*E2:K2} -> 0.13 | F21: 0.19128022 | G21: 0.24526474 | H21: 0.29796127 | I21: 0.35332051 | J21: 0.41417545 | K21: 0.48279768
A22: Battery | B22: Net | C22: Energy density | D22: kWh per liter | E22: 0.325 | F22: 0.47820056 | G22: 0.61316185 | H22: 0.74490317 | I22: 0.88330128 | J22: 1.0354386 | K22: 1.2069942
A23: Battery | B23: Net | C23: Pack cost | D23: € per kWh | E23: {=E11:K11/E2:K2} -> 415.38462 | F23: 249.86299 | G23: 174.53987 | H23: 130.58304 | I23: 101.85354 | J23: 81.995256 | K23: 67.872523 | N23: Very similar to means of near-market until 2030, then scientific until 2040, then extrapolation, from https://www.nature.com/articles/s41560-024-01531-9/figures/1
A24: Battery | B24: Net | C24: Production emissions | D24: kg CO₂ per kWh | E24: {=E12:K12/E2:K2} -> 230.76923 | F24: 119.833 | G24: 71.406321 | H24: 44.909397 | I24: 28.936996 | J24: 18.860934 | K24: 12.362538
A26: Battery | B26: Gross | C26: Residual value if recycled this year | D26: ratio | E26: {=0.3/(1+EXP(-(E$1:K$1-2035)*0.3))} -> 0.0032960828 | F26: 0.014227762 | G26: 0.054727657 | H26: 0.15 | I26: 0.24527234 | J26: 0.28577224 | K26: 0.29670392 | O26: Replaced by equation in simulation. Calculated based on price of new batteries in year of decommissioning.
A27: Battery | B27: Net | C27: Residual value if recycled this year | D27: ratio | E27: {=_xlfn.ANCHORARRAY(E26)/E2:K2} -> 0.0050708966 | F27: 0.017245772 | G27: 0.059975515 | H27: 0.15686275 | I27: 0.25075767 | J27: 0.28893244 | K27: 0.29833544 | O27: Replaced by equation in simulation. Calculated based on price of new batteries in year of decommissioning.
C28: Min useable range | D28: km | E28: 700 | F28: =E28*POWER(1+$L28,5) -> 700 | G28: =F28*POWER(1+$L28,5) -> 700 | H28: =G28*POWER(1+$L28,5) -> 700 | I28: =H28*POWER(1+$L28,5) -> 700 | J28: =I28*POWER(1+$L28,5) -> 700 | K28: =J28*POWER(1+$L28,5) -> 700 | L28: 0 | AE28: 0
B29: HGV40 | C29: Min peak power | D29: kW | E29: {=vehicles!E88:K88} -> 550 | F29: 550 | G29: 550 | H29: 550 | I29: 550 | J29: 550 | K29: 550 | AE29: Battery ageing | AF29: =OFFSET(E55,0,AE28) -> 0.24031586
C30: Minimum pack size to power motor | D30: kWh | E30: {=_xlfn.ANCHORARRAY(E29)/_xlfn.ANCHORARRAY(E8)} -> 244.44444 | F30: 200.91551 | G30: 165.13791 | H30: 135.73132 | I30: 111.56125 | J30: 91.695218 | K30: 75.366786 | AE30: Capital interest | AF30: =OFFSET(E56,0,AE28) -> 0.04263717
B31: HGV40 | C31: Energy consumption | D31: kWh per km | E31: {=vehicles!E106:K106} -> 1.1242076 | F31: 1.0908836 | G31: 1.0585475 | H31: 1.0271699 | I31: 0.99672235 | J31: 0.96717735 | K31: 0.93850813 | AE31: Lost cargo capacity | AF31: =OFFSET(E54,0,AE28) -> 0.084142613
C32: Net battery capacity | D32: kWh | E32: {=IF(E28:K28*_xlfn.ANCHORARRAY(E31)>_xlfn.ANCHORARRAY(E30)*E2:K2,E28:K28*_xlfn.ANCHORARRAY(E31),_xlfn.ANCHORARRAY(E30)*E2:K2)} -> 786.9453 | F32: 763.61855 | G32: 740.98325 | H32: 719.01891 | I32: 697.70564 | J32: 677.02415 | K32: 656.95569 | AE32: Lost time | AF32: =OFFSET(E69,0,AE28) -> 0.025427077
B33: HGV40 | C33: {=vehicles!C84:K84} -> Annual distance | D33: km | E33: 115000 | F33: 115000 | G33: 115000 | H33: 115000 | I33: 115000 | J33: 115000 | K33: 115000 | AE33: CO₂ (SCC) | AF33: =OFFSET(E75,0,AE28) -> 0.0090825113
C34: Annual energy use | D34: kWh | E34: {=E33:K33*_xlfn.ANCHORARRAY(E31)} -> 129283.87 | F34: 125451.62 | G34: 121732.96 | H34: 118124.54 | I34: 114623.07 | J34: 111225.4 | K34: 107928.44 | AE34: 0
C35: Ratio of energy directly to propulsion | D35: % of energy | E35: 0.4 | F35: =E35*POWER(1+$L35,5) -> 0.4 | G35: =F35*POWER(1+$L35,5) -> 0.4 | H35: =G35*POWER(1+$L35,5) -> 0.4 | I35: =H35*POWER(1+$L35,5) -> 0.4 | J35: =I35*POWER(1+$L35,5) -> 0.4 | K35: =J35*POWER(1+$L35,5) -> 0.4 | L35: 0
C36: Cycles per year, net | D36: cycle eq. of energy use | E36: {=(1-E35:K35)*_xlfn.ANCHORARRAY(E34)/_xlfn.ANCHORARRAY(E32)} -> 98.571429 | F36: 98.571429 | G36: 98.571429 | H36: 98.571429 | I36: 98.571429 | J36: 98.571429 | K36: 98.571429
B37: HGV40 | C37: Battery weight | D37: ton | E37: {=_xlfn.ANCHORARRAY(E32)/(E2:K2*E9:K9*1000)} -> 6.0534254 | F37: 3.9921459 | G37: 3.0211569 | H37: 2.4131288 | I37: 1.9747103 | J37: 1.6346313 | K37: 1.3607267
C38: {=vehicles!C90:K90} -> Cargo capacity value | D38: euro per ton-km | E38: 0.025 | F38: 0.025 | G38: 0.025 | H38: 0.025 | I38: 0.025 | J38: 0.025 | K38: 0.025
C39: Cost of weight | D39: euro per cycled kWh | E39: {=E38:K38*_xlfn.ANCHORARRAY(E37)/_xlfn.ANCHORARRAY(E31)} -> 0.13461538 | F39: 0.09148881 | G39: 0.071351471 | H39: 0.058732466 | I39: 0.049530099 | J39: 0.042252625 | K39: 0.036247068
B40: HGV40 | C40: Battery volume | D40: m3 | E40: {=_xlfn.ANCHORARRAY(E32)/(E2:K2*E10:K10*1000)} -> 2.4213702 | F40: 1.5968583 | G40: 1.2084627 | H40: 0.96525151 | I40: 0.78988411 | J40: 0.65385252 | K40: 0.54429068
C41: {=vehicles!C91:K91} -> Cargo capacity value | D41: euro per m3-km | E41: 0.007 | F41: 0.007 | G41: 0.007 | H41: 0.007 | I41: 0.007 | J41: 0.007 | K41: 0.007
...

Sheet bat plots
C17: 2020 | D17: 2025 | E17: 2030 | F17: 2035 | G17: 2040 | H17: 2045 | I17: 2050 | M17: 2020 | N17: 2025 | O17: 2030 | P17: 2035 | Q17: 2040 | R17: 2045 | S17: 2050
A18: Min usable range | B18: 100 | C18: 47.007859 | D18: 34.433249 | E18: 27.405201 | F18: 24.080284 | G18: 22.12328 | H18: 19.539022 | I18: 17.64977 | K18: Min usable range | L18: 100 | M18: 47.007859 | N18: 37.385148 | O18: 31.261046 | P18: 27.76917 | Q18: 25.566391 | R18: 22.831916 | S18: 20.790056
B19: 133.35214 | C19: 47.007859 | D19: 33.780518 | E19: 24.745821 | F19: 19.009405 | G19: 15.440586 | H19: 13.024816 | I19: 11.293314 | L19: 133.35214 | M19: 47.007859 | N19: 36.752664 | O19: 28.694635 | P19: 22.913814 | Q19: 19.252407 | R19: 16.758178 | S19: 14.929041
B20: 177.82794 | C20: 41.63618 | D20: 27.88761 | E20: 19.152885 | F20: 13.835893 | G20: 10.643812 | H20: 8.5393226 | I20: 7.0752252 | L20: 177.82794 | M20: 41.63618 | N20: 31.038349 | O20: 23.346245 | P20: 18.105845 | Q20: 14.954638 | R20: 12.861504 | S20: 11.371857
B21: 237.13737 | C21: 38.042117 | D21: 24.320113 | E21: 15.683007 | F21: 10.645883 | G21: 7.6850439 | H21: 5.7694621 | I21: 4.4709868 | L21: 237.13737 | M21: 38.042117 | N21: 27.701686 | O21: 20.203359 | P21: 15.425818 | Q21: 12.66822 | R21: 10.878025 | S21: 9.6491132
B22: 316.22777 | C22: 36.916304 | D22: 22.79174 | E22: 13.979517 | F22: 9.018163 | G22: 6.1003721 | H22: 4.2252134 | I22: 2.973457 | L22: 316.22777 | M22: 36.916304 | N22: 26.469169 | O22: 18.948414 | P22: 14.50298 | Q22: 11.985942 | R22: 10.383302 | S22: 9.3271857
B23: 421.6965 | C23: 37.807927 | D23: 22.843058 | E23: 13.642523 | F23: 8.5596424 | G23: 5.6844608 | H23: 4.0647652 | I23: 2.9625574 | L23: 421.6965 | M23: 37.807927 | N23: 26.898048 | O23: 19.239207 | P23: 15.007763 | Q23: 12.77776 | R23: 11.623005 | S23: 10.884046
B24: 562.34133 | C24: 40.611085 | D24: 24.326124 | E24: 14.734465 | F24: 10.053481 | G24: 7.1324866 | H24: 5.1717345 | I24: 3.8112977 | L24: 562.34133 | M24: 40.611085 | N24: 28.866594 | O24: 21.213245 | P24: 17.805204 | Q24: 15.839321 | R24: 14.59748 | S24: 13.82347
B25: 749.89421 | C25: 45.438093 | D25: 27.470482 | E25: 18.00576 | F25: 12.585399 | G25: 9.064291 | H25: 6.6479669 | I25: 4.9431161 | L25: 749.89421 | M25: 45.438093 | N25: 32.650181 | O25: 25.711136 | P25: 22.089294 | Q25: 19.924737 | R25: 18.564296 | S25: 17.743285
B26: 1000 | C26: 52.583449 | D26: 33.14623 | E26: 22.422686 | F26: 15.968059 | G26: 11.640905 | H26: 8.6165932 | I26: 6.452423 | L26: 1000 | M26: 52.583449 | N26: 39.192492 | O26: 31.808645 | P26: 27.817703 | Q26: 25.374426 | R26: 23.854306 | S26: 22.970459
B27: 1333.5214 | C27: 62.562248 | D27: 40.823478 | E27: 28.354254 | F27: 20.482887 | G27: 15.077184 | H27: 11.241822 | I27: 8.465118 | L27: 1333.5214 | M27: 62.562248 | N27: 48.063298 | O27: 40.01544 | P27: 35.466446 | Q27: 32.642731 | R27: 30.908751 | S27: 29.941019

Sheet electricity price curves
A1: hour of day | B1: Average of SE1 | C1: Average of SE2 | D1: Average of SE3 | E1: Average of SE4 | F1: Avg of DE-LU | H1: Norm SE1 | I1: Norm SE2 | J1: Norm SE3 | K1: Norm SE4
A2: 0 | B2: 36.990822 | C2: 36.990822 | D2: 42.218301 | E2: 55.548164 | F2: 81.629342 | H2: {=(B2:B25-MIN(B2:B25))/(MAX(B2:B25)-MIN(B2:B25))} -> 0.17581161 | I2: {=(C2:C25-MIN(C2:C25))/(MAX(C2:C25)-MIN(C2:C25))} -> 0.1745215 | J2: {=(D2:D25-MIN(D2:D25))/(MAX(D2:D25)-MIN(D2:D25))} -> 0.0833495 | K2: {=(E2:E25-MIN(E2:E25))/(MAX(E2:E25)-MIN(E2:E25))} -> 0.11415546
A3: 1 | B3: 35.669534 | C3: 35.669534 | D3: 39.641589 | E3: 51.892 | F3: 76.48011 | H3: 0.084069837 | I3: 0.083452928 | J3: 0.032668253 | K3: 0.051017005
A4: 2 | B4: 34.67074 | C4: 34.67074 | D4: 38.161096 | E4: 49.407205 | F4: 73.568904 | H4: 0.014719926 | I4: 0.01461191 | J4: 0.0035484956 | K4: 0.0081069867
A5: 3 | B5: 34.45874 | C5: 34.45874 | D5: 37.980685 | E5: 48.937753 | F5: 71.295288 | H5: 0 | I5: 0 | J5: 0 | K5: 0
A6: 4 | B6: 35.411342 | C6: 35.411342 | D6: 39.86389 | E6: 51.194055 | F6: 72.421945 | H6: 0.066142649 | I6: 0.06565729 | J6: 0.037040689 | K6: 0.03896416
A7: 5 | B7: 37.960438 | C7: 37.954274 | D7: 46.132795 | E7: 57.525863 | F7: 78.102795 | H7: 0.24313558 | I7: 0.24092657 | J7: 0.1603435 | K7: 0.14830841
A8: 6 | B8: 41.062932 | C8: 41.048247 | D8: 59.311973 | E8: 77.939315 | F8: 95.316575 | H8: 0.45855289 | I8: 0.45417586 | J8: 0.4195642 | K8: 0.50082915
A9: 7 | B9: 44.892685 | C9: 44.950247 | D9: 76.736685 | E9: 97.677589 | F9: 112.38271 | H9: 0.7244665 | I9: 0.72311771 | J9: 0.76229013 | K9: 0.84169021
A10: 8 | B10: 48.860986 | C10: 48.967452 | D10: 88.55926 | E10: 106.84485 | F10: 118.65364 | H10: 1 | I10: 1 | J10: 0.99482787 | K10: 1
A11: 9 | B11: 48.387808 | C11: 48.494493 | D11: 86.461315 | E11: 102.40334 | F11: 112.35071 | H11: 0.96714554 | I11: 0.96740173 | J11: 0.95356348 | K11: 0.92329944
A12: 10 | B12: 47.398795 | C12: 47.481014 | D12: 83.152384 | E12: 96.26326 | F12: 104.57049 | H12: 0.89847474 | I12: 0.89754857 | J12: 0.88848024 | K12: 0.81726611
A13: 11 | B13: 46.065781 | C13: 46.157452 | D13: 79.696959 | E13: 92.132027 | F13: 100.40745 | H13: 0.80591879 | I13: 0.80632327 | J13: 0.82051564 | K13: 0.74592368
A14: 12 | B14: 45.407836 | C14: 45.456027 | D14: 76.134192 | E14: 87.451452 | F14: 95.088603 | H14: 0.76023528 | I14: 0.7579782 | J14: 0.75043972 | K14: 0.66509463
... A25: 23 | B25: 37.442137 | C25: 37.435534 | D25: 44.660493 | E25: 59.560767 | F25: 84.852767 | H25: 0.20714805 | I25: 0.2051729 | J25: 0.13138487 | K25: 0.18344926
A26: Min | B26: =MIN(B2:B25) -> 34.45874 | C26: =MIN(C2:C25) -> 34.45874 | D26: =MIN(D2:D25) -> 37.980685 | E26: =MIN(E2:E25) -> 48.937753 | F26: =MIN(F2:F25) -> 71.295288 | H26: =AVERAGE(_xlfn.ANCHORARRAY(H2)) -> 0.55779397 | I26: =AVERAGE(_xlfn.ANCHORARRAY(I2)) -> 0.55794904 | J26: =AVERAGE(_xlfn.ANCHORARRAY(J2)) -> 0.55110628 | K26: =AVERAGE(_xlfn.ANCHORARRAY(K2)) -> 0.54534204
A27: Max | B27: =MAX(B2:B25) -> 48.860986 | C27: =MAX(C2:C25) -> 48.967452 | D27: =MAX(D2:D25) -> 88.822219 | E27: =MAX(E2:E25) -> 106.84485 | F27: =MAX(F2:F25) -> 125.2554
A28: Avg | B28: =AVERAGE(B2:B25) -> 42.492226 | C28: =AVERAGE(C2:C25) -> 42.553862 | D28: =AVERAGE(D2:D25) -> 65.999774 | E28: =AVERAGE(E2:E25) -> 80.516927 | F28: =AVERAGE(F2:F25) -> 96.849918
B30: Average Nordpool spot 2021, €/MWh

Sheet infra
A1: group | B1: subgroup | C1: variable | D1: unit | E1: 2020 | F1: 2025 | G1: 2030 | H1: 2035 | I1: 2040 | J1: 2045 | K1: 2050 | L1: Annual change | M1: Source | N1: Comment
A2: Infrastructure | B2: ERS | C2: base cost | D2: euro per km | E2: 1500000 | F2: {=E2*POWER(1+$L2,F$1:K$1-$E$1)} -> 1426485.1 | G2: 1356573.1 | H2: 1290087.5 | I2: 1226860.4 | J2: 1166732 | K2: 1109550.6 | L2: -0.01 | M2: See comment | N2: Increased from 1.2m to 1.5m after Hallsberg. ERS cost parameters are aggregates of numbers from Siemens, Elonroad and Electreon, provided in private communication. Representatives did not wish to be individually quoted. Numbers are inherrently speculative and based on cost levels reached during scale-up of technology so far built at pilot scale. | T2: kW | U2: 3000 | V2: 3000 | W2: 3000 | X2: 3000 | Y2: 3000 | Z2: 3000 | AA2: 3000
A3: Infrastructure | B3: ERS | C3: power cost | D3: euro per kW-km | E3: 700 | F3: {=E3*POWER(1+$L3,F$1:K$1-$E$1)} -> 665.69303 | G3: 633.06745 | H3: 602.04085 | I3: 572.53486 | J3: 544.47495 | K3: 517.79026 | L3: -0.01 | M3: See comment | N3: Increased from 150 to 700 after Hallsberg.
A4: Infrastructure | B4: ERS | C4: maintenance cost | D4: ratio per year | E4: 0.02 | F4: {=E4*POWER(1+$L4,F$1:K$1-$E$1)} -> 0.02 | G4: 0.02 | H4: 0.02 | I4: 0.02 | J4: 0.02 | K4: 0.02 | L4: 0 | M4: See comment | U4: {=E1:K1} -> 2020 | V4: 2025 | W4: 2030 | X4: 2035 | Y4: 2040 | Z4: 2045 | AA4: 2050
A5: Infrastructure | B5: ERS | C5: write off period | D5: years | E5: 25 | F5: {=E5*POWER(1+$L5,F$1:K$1-$E$1)} -> 25 | G5: 25 | H5: 25 | I5: 25 | J5: 25 | K5: 25 | L5: 0 | M5: See comment | T5: ERS (base) | U5: =E2 -> 1500000 | V5: =F2 -> 1426485.1 | W5: =G2 -> 1356573.1 | X5: =H2 -> 1290087.5 | Y5: =I2 -> 1226860.4 | Z5: =J2 -> 1166732 | AA5: =K2 -> 1109550.6 | AD5: 3000000
A6: Infrastructure | B6: ERS | C6: profit margin | D6: ratio | E6: {=E24:K24} -> 0.1 | F6: 0.1 | G6: 0.1 | H6: 0.1 | I6: 0.1 | J6: 0.1 | K6: 0.1 | M6: Same as station | T6: ERS (power) | U6: =U2*E3 -> 2100000 | V6: =V2*F3 -> 1997079.1 | W6: =W2*G3 -> 1899202.4 | X6: =X2*H3 -> 1806122.5 | Y6: =Y2*I3 -> 1717604.6 | Z6: =Z2*J3 -> 1633424.9 | AA6: =AA2*K3 -> 1553370.8 | AD6: 1500000
A7: Infrastructure | B7: ERS | C7: pick up cost base light | D7: euro | E7: 500 | F7: {=E7*POWER(1+$L7,F$1:K$1-$E$1)} -> 451.9604 | G7: 408.5364 | H7: 369.28455 | I7: 333.80399 | J7: 301.73236 | K7: 272.74216 | L7: -0.02 | M7: See comment | T7: Grid connections | U7: =(E44+E45*U2*E18+E17)/E18 -> 901500 | V7: =(F44+F45*V2*F18+F17)/F18 -> 901500 | W7: =(G44+G45*W2*G18+G17)/G18 -> 901500 | X7: =(H44+H45*X2*H18+H17)/H18 -> 901500 | Y7: =(I44+I45*Y2*I18+I17)/I18 -> 901500 | Z7: =(J44+J45*Z2*J18+J17)/J18 -> 901500 | AA7: =(K44+K45*AA2*K18+K17)/K18 -> 901500 | AC7: 1500 | AD7: =(AD5-AD6)/AC7 -> 1000
A8: Infrastructure | B8: ERS | C8: pick up cost base heavy | D8: euro | E8: 2000 | F8: {=E8*POWER(1+$L8,F$1:K$1-$E$1)} -> 1807.8416 | G8: 1634.1456 | H8: 1477.1382 | I8: 1335.2159 | J8: 1206.9295 | K8: 1090.9686 | L8: -0.02 | M8: See comment | T8: Capital interest | U8: =(U7+U5)*(world!E2/2)*infra!E5 -> 600375 | V8: =(V7+V5)*(world!F2/2)*infra!F5 -> 581996.27 | W8: =(W7+W5)*(world!G2/2)*infra!G5 -> 564518.28 | X8: =(X7+X5)*(world!H2/2)*infra!H5 -> 547896.88 | Y8: =(Y7+Y5)*(world!I2/2)*infra!I5 -> 532090.1 | Z8: =(Z7+Z5)*(world!J2/2)*infra!J5 -> 517058.01 | AA8: =(AA7+AA5)*(world!K2/2)*infra!K5 -> 502762.64
A9: Infrastructure | B9: ERS | C9: pick-up cost | D9: euro per kW | E9: 50 | F9: {=E9*POWER(1+$L9,F$1:K$1-$E$1)} -> 45.19604 | G9: 40.85364 | H9: 36.928455 | I9: 33.380399 | J9: 30.173236 | K9: 27.274216 | L9: -0.02 | M9: See comment | T9: Maintenance | U9: =E4*E5*(U5+U6) -> 1800000 | V9: =F4*F5*(V5+V6) -> 1711782.1 | W9: =G4*G5*(W5+W6) -> 1627887.7 | X9: =H4*H5*(X5+X6) -> 1548105 | Y9: =I4*I5*(Y5+Y6) -> 1472232.5 | Z9: =J4*J5*(Z5+Z6) -> 1400078.4 | AA9: =K4*K5*(AA5+AA6) -> 1331460.7
A10: Infrastructure | B10: ERS | C10: pick-up lifespan | D10: years | E10: 10 | F10: {=E10*POWER(1+$L10,F$1:K$1-$E$1)} -> 10 | G10: 10 | H10: 10 | I10: 10 | J10: 10 | K10: 10 | L10: 0 | M10: See comment | T10: Standardization risk | U10: =E14*E13*SUM(U5:U8) -> 765281.25 | V10: =F14*F13*SUM(V5:V8) -> 241191.84 | W10: =G14*G13*SUM(W5:W8) -> 76049.811 | X10: =H14*H13*SUM(X5:X8) -> 23990.149 | Y10: =I14*I13*SUM(Y5:Y8) -> 7571.3308 | Z10: =J14*J13*SUM(Z5:Z8) -> 2390.6781 | AA10: =K14*K13*SUM(AA5:AA8) -> 755.23949
A11: Infrastructure | B11: ERS | C11: pick up weight light | D11: kg | E11: 50 | F11: {=E11*POWER(1+$L11,F$1:K$1-$E$1)} -> 47.549502 | G11: 45.219104 | H11: 43.002918 | I11: 40.895347 | J11: 38.891068 | K11: 36.985019 | L11: -0.01 | M11: See comment | U11: =SUM(U5:U10) -> 7667156.2 | V11: =SUM(V5:V10) -> 6860034.4 | W11: =SUM(W5:W10) -> 6425731.3 | X11: =SUM(X5:X10) -> 6117702.1 | Y11: =SUM(Y5:Y10) -> 5857858.9 | Z11: =SUM(Z5:Z10) -> 5621184 | AA11: =SUM(AA5:AA10) -> 5399399.9
A12: Infrastructure | B12: ERS | C12: pick up weight heavy | D12: kg | E12: 300 | F12: {=E12*POWER(1+$L12,F$1:K$1-$E$1)} -> 285.29701 | G12: 271.31462 | H12: 258.01751 | I12: 245.37208 | J12: 233.34641 | K12: 221.91011 | L12: -0.01 | M12: See comment
A13: Infrastructure | B13: ERS | C13: standardization risk | D13: ratio | E13: 0.5 | F13: {=E13*POWER(1+$L13,F$1:K$1-$E$1)} -> 0.16384 | G13: 0.053687091 | H13: 0.017592186 | I13: 0.0057646075 | J13: 0.0018889466 | K13: 0.00061897002 | L13: -0.2 | M13: Risk of having picked a different standard than neighboring countries
A14: Infrastructure | B14: ERS | C14: cost of standard change | D14: ratio | E14: 0.3 | F14: {=E14*POWER(1+$L14,F$1:K$1-$E$1)} -> 0.3 | G14: 0.3 | H14: 0.3 | I14: 0.3 | J14: 0.3 | K14: 0.3 | L14: 0 | M14: Cost of retrofitting a new standard
A15: Infrastructure | B15: ERS | C15: utilization | D15: ratio | E15: {=H78:H79} -> 0.26531548 | F15: {=E15*POWER(1+$L15,F$1:K$1-$E$1)} -> 0.26531548 | G15: 0.26531548 | H15: 0.26531548 | I15: 0.26531548 | J15: 0.26531548 | K15: 0.26531548 | L15: 0
A16: Infrastructure | B16: ERS | C16: electricity price | D16: ratio | E16: 0.72604476 | F16: {=E16*POWER(1+$L16,F$1:K$1-$E$1)} -> 0.72604476 | G16: 0.72604476 | H16: 0.72604476 | I16: 0.72604476 | J16: 0.72604476 | K16: 0.72604476 | L16: 0
A17: Infrastructure | B17: ERS | C17: grid connection cable | D17: euro | E17: =20*500 -> 10000 | F17: {=E17*POWER(1+$L17,F$1:K$1-$E$1)} -> 10000 | G17: 10000 | H17: 10000 | I17: 10000 | J17: 10000 | K17: 10000 | L17: 0 | M17: 20 euro/m, 500 m (All digging costs from: https://www.diva-portal.org/smash/get/diva2:207284/FULLTEXT01.pdf)
A18: Infrastructure | B18: ERS | C18: grid connection interval | D18: km | E18: 10 | F18: {=E18*POWER(1+$L18,F$1:K$1-$E$1)} -> 10 | G18: 10 | H18: 10 | I18: 10 | J18: 10 | K18: 10 | L18: 0 | M18: See comment
A19: Infrastructure | B19: ERS | C19: reference | D19: aadt | E19: 2000 | F19: {=E19*POWER(1+$L19,F$1:K$1-$E$1)} -> 2000 | G19: 2000 | H19: 2000 | I19: 2000 | J19: 2000 | K19: 2000 | L19: 0 | M19: Bidirectional AADT Heavy in Sweden is ~4k on the largest roads. Assume half use ERS.
A20: Infrastructure | B20: Rest Stop | C20: hardware cost | D20: euro per kW | E20: 300 | F20: {=E20*POWER(1+$L20,F$1:K$1-$E$1)} -> 285.29701 | G20: 271.31462 | H20: 258.01751 | I20: 245.37208 | J20: 233.34641 | K20: 221.91011 | L20: -0.01 | M20: 300 from Andreas Kammel. 500 (probably includes grid) from a mix of Trafikverket, Karlström 2020 ("Kunskapssammanställning stationär laddning till tunga lastbilar"), Scania offer, Future Energy (FE). FE clearly states that hardware cost per kW increases with higher power.
A21: Infrastructure | B21: Rest Stop | C21: hardware maintenance | D21: ratio per year | E21: 0.1 | F21: {=E21*POWER(1+$L21,F$1:K$1-$E$1)} -> 0.097524875 | G21: 0.095111013 | H21: 0.092756897 | I21: 0.090461048 | J21: 0.088222024 | K21: 0.086038419 | L21: -0.005 | M21: Guess based on discussions with ChargeNode
A22: Infrastructure | B22: Rest Stop | C22: grid connection cable | D22: euro | E22: =20*750 -> 15000 | F22: {=E22*POWER(1+$L22,F$1:K$1-$E$1)} -> 15000 | G22: 15000 | H22: 15000 | I22: 15000 | J22: 15000 | K22: 15000 | L22: 0 | M22: 20 euro/m, 750 m
A23: Infrastructure | B23: Rest Stop | C23: write off period | D23: years | E23: 15 | F23: =E23+$L23*(F$1-E$1) -> 15 | G23: =F23+$L23*(G$1-F$1) -> 15 | H23: =G23+$L23*(H$1-G$1) -> 15 | I23: =H23+$L23*(I$1-H$1) -> 15 | J23: =I23+$L23*(J$1-I$1) -> 15 | K23: =J23+$L23*(K$1-J$1) -> 15 | L23: 0 | M23: TRV says 25. Kristoffer Ahlén, Price and Product Manager at Preem, says 10.
A24: Infrastructure | B24: Rest Stop | C24: profit margin | D24: ratio | E24: 0.1 | F24: {=E24*POWER(1+$L24,F$1:K$1-$E$1)} -> 0.1 | G24: 0.1 | H24: 0.1 | I24: 0.1 | J24: 0.1 | K24: 0.1 | L24: 0 | M24: Guess
A25: Infrastructure | B25: Rest Stop | C25: utilization | D25: ratio | E25: {=G78:G79} -> 0.19898661 | F25: {=E25*POWER(1+$L25,F$1:K$1-$E$1)} -> 0.19898661 | G25: 0.19898661 | H25: 0.19898661 | I25: 0.19898661 | J25: 0.19898661 | K25: 0.19898661 | L25: 0
A26: Infrastructure | B26: Rest Stop | C26: electricity price | D26: ratio | E26: 0.72604476 | F26: {=E26*POWER(1+$L26,F$1:K$1-$E$1)} -> 0.72604476 | G26: 0.72604476 | H26: 0.72604476 | I26: 0.72604476 | J26: 0.72604476 | K26: 0.72604476 | L26: 0
A27: Infrastructure | B27: Rest Stop | C27: reference | D27: vehicles per day | E27: 100 | F27: {=E27*POWER(1+$L27,F$1:K$1-$E$1)} -> 100 | G27: 100 | H27: 100 | I27: 100 | J27: 100 | K27: 100 | L27: 0 | M27: Seed value. Bidirectional AADT Heavy in Sweden is ~4k on the largest roads. If vehicles must stop every 5th opportunity and half use stations.
A28: Infrastructure | B28: Depot | C28: hardware cost | D28: euro per kW | E28: =E20 -> 300 | F28: {=E28*POWER(1+$L28,F$1:K$1-$E$1)} -> 285.29701 | G28: 271.31462 | H28: 258.01751 | I28: 245.37208 | J28: 233.34641 | K28: 221.91011 | L28: -0.01
A29: Infrastructure | B29: Depot | C29: hardware maintenance | D29: ratio per year | E29: 0.1 | F29: {=E29*POWER(1+$L29,F$1:K$1-$E$1)} -> 0.097524875 | G29: 0.095111013 | H29: 0.092756897 | I29: 0.090461048 | J29: 0.088222024 | K29: 0.086038419 | L29: -0.005 | M29: Guess based on discussions with ChargeNode
A30: Infrastructure | B30: Depot | C30: grid connection cable | D30: euro | E30: =50*100 -> 5000 | F30: {=E30*POWER(1+$L30,F$1:K$1-$E$1)} -> 5000 | G30: 5000 | H30: 5000 | I30: 5000 | J30: 5000 | K30: 5000 | L30: 0 | M30: 50 euro/m, 100 m
A31: Infrastructure | B31: Depot | C31: write off period | D31: years | E31: 7 | F31: =E31+$L31*(F$1-E$1) -> 7 | G31: =F31+$L31*(G$1-F$1) -> 7 | H31: =G31+$L31*(H$1-G$1) -> 7 | I31: =H31+$L31*(I$1-H$1) -> 7 | J31: =I31+$L31*(J$1-I$1) -> 7 | K31: =J31+$L31*(K$1-J$1) -> 7 | L31: 0 | M31: Guess
A32: Infrastructure | B32: Depot | C32: profit margin | D32: ratio | E32: 0.1 | F32: {=E32*POWER(1+$L32,F$1:K$1-$E$1)} -> 0.1 | G32: 0.1 | H32: 0.1 | I32: 0.1 | J32: 0.1 | K32: 0.1 | L32: 0 | M32: Guess, haulier rents infra
A33: Infrastructure | B33: Depot | C33: utilization | D33: ratio | E33: {=E78:E79} -> 0.34132097 | F33: {=E33*POWER(1+$L33,F$1:K$1-$E$1)} -> 0.34132097 | G33: 0.34132097 | H33: 0.34132097 | I33: 0.34132097 | J33: 0.34132097 | K33: 0.34132097 | L33: 0
A34: Infrastructure | B34: Depot | C34: electricity price | D34: ratio | E34: 0.37642925 | F34: {=E34*POWER(1+$L34,F$1:K$1-$E$1)} -> 0.37642925 | G34: 0.37642925 | H34: 0.37642925 | I34: 0.37642925 | J34: 0.37642925 | K34: 0.37642925 | L34: 0
A35: Infrastructure | B35: Depot | C35: reference | D35: vehicles per day | E35: 20 | F35: {=E35*POWER(1+$L35,F$1:K$1-$E$1)} -> 20 | G35: 20 | H35: 20 | I35: 20 | J35: 20 | K35: 20 | L35: 0 | M35: Seed value. Guess. | V35: AADT | W35: 4000
A36: Infrastructure | B36: Destination | C36: hardware cost | D36: euro per kW | E36: =E20 -> 300 | F36: {=E36*POWER(1+$L36,F$1:K$1-$E$1)} -> 285.29701 | G36: 271.31462 | H36: 258.01751 | I36: 245.37208 | J36: 233.34641 | K36: 221.91011 | L36: -0.01 | V36: km/h | W36: 85
A37: Infrastructure | B37: Destination | C37: hardware maintenance | D37: ratio per year | E37: 0.1 | F37: {=E37*POWER(1+$L37,F$1:K$1-$E$1)} -> 0.097524875 | G37: 0.095111013 | H37: 0.092756897 | I37: 0.090461048 | J37: 0.088222024 | K37: 0.086038419 | L37: -0.005 | M37: As rest stop | V37: Peak trucks/h | W37: =(W35/24)/H78 -> 628.18298
A38: Infrastructure | B38: Destination | C38: grid connection cable | D38: euro | E38: =E30 -> 5000 | F38: {=E38*POWER(1+$L38,F$1:K$1-$E$1)} -> 5000 | G38: 5000 | H38: 5000 | I38: 5000 | J38: 5000 | K38: 5000 | L38: 0 | M38: As depot | V38: Peak trucks/km | W38: =W37/W36 -> 7.390388
A39: Infrastructure | B39: Destination | C39: write off period | D39: years | E39: 10 | F39: =E39+$L39*(F$1-E$1) -> 10 | G39: =F39+$L39*(G$1-F$1) -> 10 | H39: =G39+$L39*(H$1-G$1) -> 10 | I39: =H39+$L39*(I$1-H$1) -> 10 | J39: =I39+$L39*(J$1-I$1) -> 10 | K39: =J39+$L39*(K$1-J$1) -> 10 | L39: 0 | M39: Guess | V39: Mean kW/truck-km | W39: 150
A40: Infrastructure | B40: Destination | C40: profit margin | D40: ratio | E40: 0.1 | F40: {=E40*POWER(1+$L40,F$1:K$1-$E$1)} -> 0.1 | G40: 0.1 | H40: 0.1 | I40: 0.1 | J40: 0.1 | K40: 0.1 | L40: 0 | M40: As depot | V40: Coverage | W40: 0.4
...

Sheet world
A1: group | B1: subgroup | C1: variable | D1: unit | E1: 2020 | F1: 2025 | G1: 2030 | H1: 2035 | I1: 2040 | J1: 2045 | K1: 2050 | L1: Annual change | M1: Sources | N1: Comments
A2: World | B2: Economy | C2: Public sector interest rate | D2: percent | E2: 0.02 | F2: {=E2*POWER(1+$L2,F$1:K$1-$E$1)} -> 0.02 | G2: 0.02 | H2: 0.02 | I2: 0.02 | J2: 0.02 | K2: 0.02 | L2: 0 | M2: https://www.pwc.se/sv/pdf-reports/corporate-finance/riskpremiestudien-2021.pdf, https://www.riksgalden.se/sv/var-verksamhet/statslanerantan/ | N2: Statslåneräntan speglar den riskfria räntan (se riksgalden.se). Tar medelvärde av PWC-studien och senaste 50-åriga statsobligationen som gavs ut.
A3: World | B3: Economy | C3: Private sector interest public charging and trucks | D3: percent | E3: 0.03 | F3: {=E3*POWER(1+$L3,F$1:K$1-$E$1)} -> 0.03 | G3: 0.03 | H3: 0.03 | I3: 0.03 | J3: 0.03 | K3: 0.03 | L3: 0 | M3: 6% above base interest, companies with credit rating AAA/AA (https://firmalan.com/sv/lana-pengar/jamfor-lan/)
A4: World | B4: Economy | C4: Private sector interest depot charging | D4: percent | E4: 0.07 | F4: {=E4*POWER(1+$L4,F$1:K$1-$E$1)} -> 0.07 | G4: 0.07 | H4: 0.07 | I4: 0.07 | J4: 0.07 | K4: 0.07 | L4: 0 | M4: 10% above base interest. Depot chargers should offer poor security. (https://firmalan.com/sv/lana-pengar/jamfor-lan/)
A5: World | B5: Economy | C5: Heavy traffic volume vs 2020 | D5: percent | E5: 2.5 | F5: {=E5*POWER(1+$L5,F$1:K$1-$E$1)} -> 2.6667803 | G5: 2.8446868 | H5: 3.0344619 | I5: 3.2368973 | J5: 3.4528375 | K5: 3.6831836 | L5: 0.013 | M5: Trafikverket's base forecast for road cargo 2017-2040, Fig 6.4 (https://trafikverket.diva-portal.org/smash/get/diva2:1749263/FULLTEXT01.pdf)
A6: World | B6: Economy | C6: Logistic BEV penalty | D6: percent | E6: 0.15 | F6: {=_xlfn.SEQUENCE(1,6,E6+(L6-E6)/6,(L6-E6)/6)} -> 0.125 | G6: 0.1 | H6: 0.075 | I6: 0.05 | J6: 0.025 | K6: 0 | L6: 0 | M6: Guess | N6: Based on reasoning that BEVs will be less flexible/viable on fewer routes in the beginning. Single-route TCO must be this much lower to beat diesel.
A7: World | B7: Charging | C7: Extra stop overhead | D7: h | E7: =15/60 -> 0.25 | F7: {=E7*POWER(1+$L7,F$1:K$1-$E$1)} -> 0.21468351 | G7: 0.18435603 | H7: 0.1583128 | I7: 0.13594859 | J7: 0.11674368 | K7: 0.10025177 | L7: -0.03 | M7: Guess. Getting to the charger, plugging in, paying, battery conditioning, will get smoother. | N7: Getting to the charger, plugging in, paying, battery conditioning, will get smoother
A8: World | B8: CO₂ | C8: SCC | D8: euro per kg | E8: 0.08 | F8: =AVERAGE(E8,G8) -> 0.165 | G8: 0.25 | H8: =AVERAGE(G8,I8) -> 0.3875 | I8: 0.525 | J8: =AVERAGE(I8,K8) -> 0.6625 | K8: 0.8 | M8: https://www.eib.org/attachments/lucalli/20240105_eib_sasb_report_2023_en.pdf | N8: EIB shadow cost of carbon
A9: World | B9: CO₂ | C9: Tax | D9: ratio of SCC | E9: 0.7 | F9: =E9+$L9 -> 0.75 | G9: =F9+$L9 -> 0.8 | H9: =G9+$L9 -> 0.85 | I9: =H9+$L9 -> 0.9 | J9: =I9+$L9 -> 0.95 | K9: =J9+$L9 -> 1 | L9: 0.05 | M9: To match current CO₂ tax.
A10: World | B10: FossilDiesel | C10: Price | D10: euro per liter | E10: 0.6 | F10: {=E10*POWER(1+$L10,F$1:K$1-$E$1)} -> 0.63687443 | G10: 0.67601507 | H10: 0.71756118 | I10: 0.76166062 | J10: 0.80847029 | K10: 0.85815676 | L10: 0.012 | M10: Approximate product cost in Sweden in april 2023, estimated from product costs of FAME and HVO and blend ratios. Highly unreliable forecast.
A11: World | B11: RenewableDiesel | C11: Price | D11: euro per liter | E11: 1.5 | F11: =E11 -> 1.5 | G11: {=F11*POWER(1+$L11,G$1:K$1-$F$1)} -> 1.5921861 | H11: 1.6900377 | I11: 1.793903 | J11: 1.9041515 | K11: 2.0211757 | L11: 0.012 | M11: alliance.eu/efuels/costs-outlook), which is likely a biased source. | N11: Probably need to vary this in experiments
A12: World | B12: RenewableDiesel | C12: Supply cap | D12: liter per year | E12: =E13*0.35*4000000000*E5 -> 175000000 | F12: {=E12*POWER(1+$L12,F$1:K$1-$E$1)} -> 1.9321414e+08 | G12: 2.1332402e+08 | H12: 2.3552696e+08 | I12: 2.6004079e+08 | J12: 2.8710605e+08 | K12: 3.1698828e+08 | L12: 0.02 | M12: "Blend guess" ratio of total fuel used in 2020 according to the simulation. | N12: In 2018: All diesel for trucks and cars = 56.3 TWh/y, 23% renewable, diesel 10 kWh/liter = 1.259e9 liter/year. I ended up ignoring that number and set this based on total fuel in the sim instead. Biofuels seem to contribute around 7% of total transport energy in 2022 (https://www.epure.org/wp-content/uploads/2022/10/221011-DEF-REP-Overview-of-biofuels-policies-and-markets-across-the-EU-October-2022.pdf) | O12: Sweden already uses a large percentage of the world supply
A13: World | B13: RenewableDiesel | C13: Blend guess | D13: ratio | E13: 0.05 | F13: 0.06 | G13: 0.08 | H13: =1-(1-G13)*(1-$L13)^5 -> 0.28812154 | I13: =1-(1-H13)*(1-$L13)^5 -> 0.44916202 | J13: =1-(1-I13)*(1-$L13)^5 -> 0.57377207 | K13: =1-(1-J13)*(1-$L13)^5 -> 0.67019295 | L13: 0.05 | M13: https://www.energimyndigheten.se/globalassets/nyheter/2020/er-2020_26-drivmedel-2019.pdf | N13: High ratio is enabled by lower diesel consumption due to electrification | O13: It's complicated. Reduktionsplikten for 2020 is 30% CO2e reduction for diesel, which requires >30% biofuels. Actual sales seem to amount to 29% renewables for diesel + HVO100 + FAME100. Forecast based on a mix of Swedish reduktionsplikt and e-Fuel Alliance forecast. Increasing share is by reduced ICEV market share.
A14: World | B14: FossilDiesel | C14: Emissions | D14: kg CO₂ per liter | E14: 3.23 | F14: {=E14*POWER(1+$L14,F$1:K$1-$E$1)} -> 3.23 | G14: 3.23 | H14: 3.23 | I14: 3.23 | J14: 3.23 | K14: 3.23 | L14: 0 | M14: Auke Hoekstra (2020) "Electric trucks: economically and environmentally desirable but misunderstood" | N14: https://www.elaad.nl/uploads/files/Auke_Hoekstra_-_Electric_trucks_economically_and_environmentally_desirable_but_misunderstood.pdf | O14: This paper says 2.8 (fig 5.1, (1060*20/(1060-850))/(36 MJ/liter)): https://theicct.org/wp-content/uploads/2021/06/LNG-in-trucks_May2020.pdf
A15: World | B15: RenewableDiesel | C15: Emissions | D15: kg CO₂ per liter | E15: 0.67 | F15: {=E15*POWER(1+$L15,F$1:K$1-$E$1)} -> 0.51843323 | G15: 0.40115375 | H15: 0.31040512 | I15: 0.24018557 | J15: 0.18585101 | K15: 0.14380797 | L15: -0.05 | M15: 2020 value from https://www.miljofordon.se/bilar/miljoepaaverkan/ Most of biodiesel's emission is from use of fossil oil, which is expected to gradually be displaced by sustainable sources.
A16: World | B16: Diesel | C16: Price | D16: euro per liter | E16: {=(1-E13:K13)*E10:K10+E13:K13*E11:K11} -> 0.645 | F16: 0.68866196 | G16: 0.74930875 | H16: 0.9977526 | I16: 1.2253047 | J16: 1.4371416 | K16: 1.6376039 | L16: n/a | M16: =""
A17: World | B17: Diesel | C17: Emissions | D17: kg CO₂ per liter | E17: {=(1-E13:K13)*E14:K14+E13:K13*E15:K15} -> 3.102 | F17: 3.067306 | G17: 3.0036923 | H17: 2.3888018 | I17: 1.8870889 | J17: 1.4833523 | K17: 1.1616559 | L17: n/a | M17: =""
A18: World | B18: Diesel | C18: CO₂ tax | D18: euro per liter | E18: {=E17:K17*E9:K9*E8:K8} -> 0.173712 | F18: 0.37957912 | G18: 0.60073846 | H18: 0.7868116 | I18: 0.89164952 | J18: 0.93358488 | K18: 0.92932468 | L18: n/a | M18: CO₂ tax on diesel in Sweden in 2022. | N18: Swedish diesel CO₂ tax is 2.5 SEK/liter as of june 2023, plus VAT which we exclude
A19: World | B19: Diesel | C19: Pollution tax | D19: euro per liter | E19: 0.02 | F19: {=E19*POWER(1+$L19,F$1:K$1-$E$1)} -> 0.0322102 | G19: 0.051874849 | H19: 0.083544963 | I19: 0.13455 | J19: 0.21669412 | K19: 0.34898805 | L19: 0.1 | M19: Guess | N19: ICEs release NOx, particles and noise. I assume these will be penalized.
A20: World | B20: Diesel | C20: Road tax | D20: euro per liter | E20: 0.4 | F20: {=E20*POWER(1+$L20,F$1:K$1-$E$1)} -> 0.4 | G20: 0.4 | H20: 0.4 | I20: 0.4 | J20: 0.4 | K20: 0.4 | L20: 0 | M20: Swedish energy tax has ranged between 1.5 and 2.5 SEK/liter. German energy tax is approx €0.5/liter.
A21: World | B21: Electricity | C21: Conversion ratio | D21: kWh per liter | E21: =vehicles!X25 -> 4.1637318 | F21: =E21 -> 4.1637318 | G21: =F21 -> 4.1637318 | H21: =G21 -> 4.1637318 | I21: =H21 -> 4.1637318 | J21: =I21 -> 4.1637318 | K21: =J21 -> 4.1637318 | L21: n/a | M21: =""
A22: World | B22: Electricity | C22: Road tax | D22: euro per kWh | E22: {=E20:K20/E21:K21} -> 0.096067668 | F22: 0.096067668 | G22: 0.096067668 | H22: 0.096067668 | I22: 0.096067668 | J22: 0.096067668 | K22: 0.096067668 | L22: n/a | M22: =""
A23: SE12 | B23: SE12 | C23: Price min | D23: euro per kWh | E23: {=E31:E33} -> 0.071295288 | F23: {=E23*POWER(1+$L23,F$1:K$1-$E$1)} -> 0.071295288 | G23: 0.071295288 | H23: 0.071295288 | I23: 0.071295288 | J23: 0.071295288 | K23: 0.071295288 | L23: {=L31:L33} -> 0 | M23: Values from OtherRegion
A24: SE12 | B24: SE12 | C24: Price max | D24: euro per kWh | E24: 0.1252554 | F24: {=E24*POWER(1+$L24,F$1:K$1-$E$1)} -> 0.1252554 | G24: 0.1252554 | H24: 0.1252554 | I24: 0.1252554 | J24: 0.1252554 | K24: 0.1252554 | L24: 0 | M24: Values from OtherRegion
A25: SE12 | B25: SE12 | C25: CO₂ emissions | D25: kg per kWh | E25: 0.265 | F25: {=E25*POWER(1+$L25,F$1:K$1-$E$1)} -> 0.1746566 | G25: 0.11511294 | H25: 0.075868812 | I25: 0.050003732 | J25: 0.032956536 | K25: 0.021721044 | L25: -0.08 | M25: Values from OtherRegion
A26: SE12 | B26: SE12 | C26: CO₂ tax | D26: euro per kWh | E26: {=E25:K25*E9:K9*E8:K8} -> 0.01484 | F26: 0.021613755 | G26: 0.023022588 | H26: 0.02498929 | I26: 0.023626763 | J26: 0.02074202 | K26: 0.017376835 | L26: n/a | M26: =""
A27: SE34 | B27: SE34 | C27: Price min | D27: euro per kWh | E27: {=E31:E33} -> 0.071295288 | F27: {=E27*POWER(1+$L27,F$1:K$1-$E$1)} -> 0.071295288 | G27: 0.071295288 | H27: 0.071295288 | I27: 0.071295288 | J27: 0.071295288 | K27: 0.071295288 | L27: {=L31:L33} -> 0 | M27: Values from OtherRegion
A28: SE34 | B28: SE34 | C28: Price max | D28: euro per kWh | E28: 0.1252554 | F28: {=E28*POWER(1+$L28,F$1:K$1-$E$1)} -> 0.1252554 | G28: 0.1252554 | H28: 0.1252554 | I28: 0.1252554 | J28: 0.1252554 | K28: 0.1252554 | L28: 0 | M28: Values from OtherRegion | P28: {=E28:K28-E27:K27} -> 0.05396011 | Q28: 0.05396011 | R28: 0.05396011 | S28: 0.05396011 | T28: 0.05396011 | U28: 0.05396011 | V28: 0.05396011
A29: SE34 | B29: SE34 | C29: CO₂ emissions | D29: kg per kWh | E29: 0.265 | F29: {=E29*POWER(1+$L29,F$1:K$1-$E$1)} -> 0.1746566 | G29: 0.11511294 | H29: 0.075868812 | I29: 0.050003732 | J29: 0.032956536 | K29: 0.021721044 | L29: -0.08 | M29: Values from OtherRegion
A30: SE34 | B30: SE34 | C30: CO₂ tax | D30: euro per kWh | E30: {=E29:K29*E9:K9*E8:K8} -> 0.01484 | F30: 0.021613755 | G30: 0.023022588 | H30: 0.02498929 | I30: 0.023626763 | J30: 0.02074202 | K30: 0.017376835 | L30: n/a | M30: =""
A31: OtherRegion | B31: OtherRegion | C31: Price min | D31: euro per kWh | E31: ='electricity price curves'!F26/1000 -> 0.071295288 | F31: {=E31*POWER(1+$L31,F$1:K$1-$E$1)} -> 0.071295288 | G31: 0.071295288 | H31: 0.071295288 | I31: 0.071295288 | J31: 0.071295288 | K31: 0.071295288 | L31: 0 | M31: Nordpool spot prices (DE-LU), min average price per hour, 2021
A32: OtherRegion | B32: OtherRegion | C32: Price max | D32: euro per kWh | E32: ='electricity price curves'!F27/1000 -> 0.1252554 | F32: {=E32*POWER(1+$L32,F$1:K$1-$E$1)} -> 0.1252554 | G32: 0.1252554 | H32: 0.1252554 | I32: 0.1252554 | J32: 0.1252554 | K32: 0.1252554 | L32: 0 | M32: Nordpool spot prices (DE-LU), max average price per hour, 2021
A33: OtherRegion | B33: OtherRegion | C33: CO₂ emissions | D33: kg per kWh | E33: 0.265 | F33: {=E33*POWER(1+$L33,F$1:K$1-$E$1)} -> 0.1746566 | G33: 0.11511294 | H33: 0.075868812 | I33: 0.050003732 | J33: 0.032956536 | K33: 0.021721044 | L33: -0.08 | M33: Greenhouse gas emission intensity of electricity generation in Europe (https://www.eea.europa.eu/ims/greenhouse-gas-emission-intensity-of-1)
A34: OtherRegion | B34: OtherRegion | C34: CO₂ tax | D34: euro per kWh | E34: {=E33:K33*E9:K9*E8:K8} -> 0.01484 | F34: 0.021613755 | G34: 0.023022588 | H34: 0.02498929 | I34: 0.023626763 | J34: 0.02074202 | K34: 0.017376835 | L34: n/a | M34: =""
C37: Effective diesel price, incl tax | D37: euro per liter | E37: {=_xlfn.ANCHORARRAY(E16)+_xlfn.ANCHORARRAY(E18)+E19:K19+E20:K20} -> 1.238712 | F37: 1.5004513 | G37: 1.8019221 | H37: 2.2681092 | I37: 2.6515042 | J37: 2.9874206 | K37: 3.3159166
C38: Effective diesel tax ratio | D38: percent | E38: {=(_xlfn.ANCHORARRAY(E18)+E19:K19+E20:K20)/_xlfn.ANCHORARRAY(E37)} -> 0.47929785 | F38: 0.54103011 | G38: 0.5841614 | H38: 0.56009498 | I38: 0.53788318 | J38: 0.51893563 | K38: 0.5061384
C39: Equivalent reduktionsplikt | D39: percent | E39: {=1-_xlfn.ANCHORARRAY(E17)/E14:K14} -> 0.039628483 | F39: 0.050369661 | G39: 0.070064303 | H39: 0.26043287 | I39: 0.41576194 | J39: 0.54075779 | K39: 0.64035422 | N39: =1.64*0.35 -> 0.574
C40: Equivalent diesel emissions | D40: kg CO₂ per kWh | E40: {=_xlfn.ANCHORARRAY(E17)/(vehicles!E106:K106/vehicles!E103:K103)} -> 0.74500476 | F40: 0.74038539 | G40: 0.72868472 | H40: 0.58243548 | I40: 0.46242739 | J40: 0.36532466 | K40: 0.28753826
C41: Electricity vs diesel cost | D41: ratio | E41: {=AVERAGE(E27:E28)*E21:K21/_xlfn.ANCHORARRAY(E16)} -> 0.63440646 | F41: 0.59418435 | G41: 0.54609287 | H41: 0.41011385 | I41: 0.33395136 | J41: 0.28472641 | K41: 0.2498725
A43: Backup of values used in RISE REPORT
...

Sheet world (SE)
A1: group | B1: subgroup | C1: variable | D1: unit | E1: 2020 | F1: 2025 | G1: 2030 | H1: 2035 | I1: 2040 | J1: 2045 | K1: 2050 | L1: Annual change | M1: Sources | N1: Comments
A2: World | B2: Economy | C2: Public sector interest rate | D2: percent | E2: 0.03 | F2: {=E2*POWER(1+$L2,F$1:K$1-$E$1)} -> 0.03 | G2: 0.03 | H2: 0.03 | I2: 0.03 | J2: 0.03 | K2: 0.03 | L2: 0 | M2: https://www.pwc.se/sv/pdf-reports/corporate-finance/riskpremiestudien-2021.pdf, samt https://www.riksgalden.se/sv/var-verksamhet/statslanerantan/ | N2: Statslåneräntan speglar den riskfria räntan (se riksgalden.se). Tar medelvärde av PWC-studien och senaste 50-åriga statsobligationen som gavs ut.
A3: World | B3: Economy | C3: Private sector interest public charging and trucks | D3: percent | E3: 0.08 | F3: {=E3*POWER(1+$L3,F$1:K$1-$E$1)} -> 0.08 | G3: 0.08 | H3: 0.08 | I3: 0.08 | J3: 0.08 | K3: 0.08 | L3: 0 | M3: https://firmalan.com/sv/lana-pengar/jamfor-lan/ | N3: +6% på basränta. Företag med hög kreditvärdighet, AAA/AA. Förutsätter att ränta rör företagslån. För stora företag är företagsobligationer ett alternativ
A4: World | B4: Economy | C4: Private sector interest depot charging | D4: percent | E4: 0.12 | F4: {=E4*POWER(1+$L4,F$1:K$1-$E$1)} -> 0.12 | G4: 0.12 | H4: 0.12 | I4: 0.12 | J4: 0.12 | K4: 0.12 | L4: 0 | M4: https://firmalan.com/sv/lana-pengar/jamfor-lan/ | N4: +10% på basränta. Företag med kreditvärdighet A/B, förutsätter företagslån. Depåladdare är sämre säkerhet än lastbilar.
A5: World | B5: Economy | C5: Heavy traffic volume vs 2020 | D5: percent | E5: 1 | F5: {=E5*POWER(1+$L5,F$1:K$1-$E$1)} -> 1.1040808 | G5: 1.2189944 | H5: 1.3458683 | I5: 1.4859474 | J5: 1.640606 | K5: 1.8113616 | L5: 0.02 | M5: https://trafikverket.diva-portal.org/smash/get/diva2:1749263/FULLTEXT01.pdf | N5: TRVs basprognos för gods på väg 2017-2040, Fig 6.4
A6: World | B6: Charging | C6: Extra stop overhead | D6: h | E6: =15/60 -> 0.25 | F6: {=E6*POWER(1+$L6,F$1:K$1-$E$1)} -> 0.21468351 | G6: 0.18435603 | H6: 0.1583128 | I6: 0.13594859 | J6: 0.11674368 | K6: 0.10025177 | L6: -0.03 | M6: Guess | N6: Getting to the charger, plugging in, paying, battery conditioning, will get smoother
A7: World | B7: CO₂ | C7: SCC | D7: euro per kg | E7: 0.7 | F7: {=E7*POWER(1+$L7,F$1:K$1-$E$1)} -> 0.7 | G7: 0.7 | H7: 0.7 | I7: 0.7 | J7: 0.7 | K7: 0.7 | L7: 0 | M7: https://www.trafikverket.se/contentassets/4b1c1005597d47bda386d81dd3444b24/asek-2021/12_klimateffekter_a70.pdf | N7: ASEK 7.0 says 7 SEK/kg. US EPA has proposed $190/ton https://www.epa.gov/system/files/documents/2022-11/epa_scghg_report_draft_0.pdf, $185/ton https://www.nature.com/articles/s41586-022-05224-9,
A8: World | B8: CO₂ | C8: Tax | D8: ratio of SCC | E8: 0.2 | F8: =E8+$L8 -> 0.25 | G8: =F8+$L8 -> 0.3 | H8: =G8+$L8 -> 0.35 | I8: =H8+$L8 -> 0.4 | J8: =I8+$L8 -> 0.45 | K8: =J8+$L8 -> 0.5 | L8: 0.05 | M8: Koldioxidskatt på 2.29 kr/liter idag. Gissning om framtiden.
A9: World | B9: FossilDiesel | C9: Price | D9: euro per liter | E9: 1 | F9: {=E9*POWER(1+$L9,F$1:K$1-$E$1)} -> 1.0510101 | G9: 1.1046221 | H9: 1.160969 | I9: 1.22019 | J9: 1.282432 | K9: 1.3478489 | L9: 0.01 | N9: Approximate product cost in Sweden in april 2023, estimated from product costs of FAME and HVO and blend ratios. Cannot forecast. Run sensitivity analysis.
A10: World | B10: RenewableDiesel | C10: Price | D10: euro per liter | E10: 2 | F10: =E10 -> 2 | G10: {=F10*POWER(1+$L10,G$1:K$1-$F$1)} -> 1.9019801 | H10: 1.8087642 | I10: 1.7201167 | J10: 1.6358139 | K10: 1.5556427 | L10: -0.01 | N10: Probably need to vary this in experiments | O10: Cannot derive cost of biofuels in Sweden. E-fuel Alliance forecasts 1.61-1.99/l @ 2025 --> 0.70-1.33 @ 2050 https://www.efuel-alliance.eu/efuels/costs-outlook
A11: World | B11: RenewableDiesel | C11: Supply cap | D11: liter per year | E11: =E12*1640000000 -> 574000000 | F11: {=E11*POWER(1+$L11,F$1:K$1-$E$1)} -> 6.0327977e+08 | G11: 6.340531e+08 | H11: 6.6639618e+08 | I11: 7.0038908e+08 | J11: 7.3611597e+08 | K11: 7.7366528e+08 | L11: 0.01 | M11: https://www.energimyndigheten.se/globalassets/statistik/drivmedel-2018.pdf | N11: In 2018: All diesel for trucks and cars = 56.3 TWh/y, 23% renewable, diesel 10 kWh/liter = 1.259e9 liter/year. I ended up ignoring that number and set this based on total fuel in the sim instead. Biofuels seem to contribute around 7% of total transport energy in 2022 (https://www.epure.org/wp-content/uploads/2022/10/221011-DEF-REP-Overview-of-biofuels-policies-and-markets-across-the-EU-October-2022.pdf) | O11: Sweden already uses a large percentage of the world supply
A12: World | B12: RenewableDiesel | C12: Blend guess | D12: ratio | E12: 0.35 | F12: 0.4 | G12: 0.5 | H12: =1-(1-G12)*(1-$L12)^5 -> 0.77814734 | I12: =1-(1-H12)*(1-$L12)^5 -> 0.9015628 | J12: =1-(1-I12)*(1-$L12)^5 -> 0.95632289 | K12: =1-(1-J12)*(1-$L12)^5 -> 0.98062023 | L12: 0.15 | M12: https://www.energimyndigheten.se/globalassets/nyheter/2020/er-2020_26-drivmedel-2019.pdf | N12: High ratio is enabled by lower diesel consumption due to electrification | O12: It's complicated. Reduktionsplikten for 2020 is 30% CO2e reduction for diesel, which requires >30% biofuels. Actual sales seem to amount to 29% renewables for diesel + HVO100 + FAME100. Forecast based on a mix of Swedish reduktionsplikt and e-Fuel Alliance forecast. Increasing share is by reduced ICEV market share.
A13: World | B13: FossilDiesel | C13: Emissions | D13: kg CO₂ per liter | E13: 3.23 | F13: {=E13*POWER(1+$L13,F$1:K$1-$E$1)} -> 3.23 | G13: 3.23 | H13: 3.23 | I13: 3.23 | J13: 3.23 | K13: 3.23 | L13: 0 | N13: Hoekstra 2020 | O13: https://www.elaad.nl/uploads/files/Auke_Hoekstra_-_Electric_trucks_economically_and_environmentally_desirable_but_misunderstood.pdf
A14: World | B14: RenewableDiesel | C14: Emissions | D14: kg CO₂ per liter | E14: 0.67 | F14: {=E14*POWER(1+$L14,F$1:K$1-$E$1)} -> 0.51843323 | G14: 0.40115375 | H14: 0.31040512 | I14: 0.24018557 | J14: 0.18585101 | K14: 0.14380797 | L14: -0.05 | N14: From Swedish source: https://www.miljofordon.se/bilar/miljoepaaverkan/ Most of biodiesel's emission is from use of fossil oil, which is expected to gradually be displaced by sustainable sources.
A15: World | B15: Diesel | C15: Price | D15: euro per liter | E15: {=(1-E12:K12)*E9:K9+E12:K12*E10:K10} -> 1.35 | F15: 1.430606 | G15: 1.5033011 | H15: 1.6650491 | I15: 1.6709053 | J15: 1.6203792 | K15: 1.5516157 | L15: n/a | M15: https://drivkraftsverige.se/statistik/priser/mer-prisstatistik/arsmedelspriser-motorbranslen/
A16: World | B16: Diesel | C16: Emissions | D16: kg CO₂ per liter | E16: {=(1-E12:K12)*E13:K13+E12:K12*E14:K14} -> 2.334 | F16: 2.1453733 | G16: 1.8155769 | H16: 0.958125 | I16: 0.53449454 | J16: 0.31881064 | K16: 0.20361765 | L16: n/a | M16: n/a
A17: World | B17: Diesel | C17: CO₂ tax | D17: euro per liter | E17: {=E16:K16*E8:K8*E7:K7} -> 0.32676 | F17: 0.37544033 | G17: 0.38127114 | H17: 0.23474063 | I17: 0.14965847 | J17: 0.10042535 | K17: 0.071266177 | L17: n/a | M17: n/a | N17: Swedish diesel CO₂ tax is 2.5 SEK/liter as of june 2023, plus VAT which we exclude
A18: World | B18: Diesel | C18: Pollution tax | D18: euro per liter | E18: 0.02 | F18: {=E18*POWER(1+$L18,F$1:K$1-$E$1)} -> 0.0322102 | G18: 0.051874849 | H18: 0.083544963 | I18: 0.13455 | J18: 0.21669412 | K18: 0.34898805 | L18: 0.1 | M18: Guess | N18: ICEs release NOx, particles and noise. I assume these will be penalized.
A19: World | B19: Diesel | C19: Road tax | D19: euro per liter | E19: 0.2 | F19: {=E19*POWER(1+$L19,F$1:K$1-$E$1)} -> 0.2 | G19: 0.2 | H19: 0.2 | I19: 0.2 | J19: 0.2 | K19: 0.2 | L19: 0 | M19: https://www.ekonomifakta.se/fakta/energi/styrmedel/konsumtionsskatter-pa-diesel/ | N19: Swedish energy tax has ranged between 1.5 and 2.5 SEK/liter. German energy tax is approx €0.5/liter.
A20: World | B20: Electricity | C20: Conversion ratio | D20: kWh per liter | E20: =vehicles!X25 -> 4.1637318 | F20: =E20 -> 4.1637318 | G20: =F20 -> 4.1637318 | H20: =G20 -> 4.1637318 | I20: =H20 -> 4.1637318 | J20: =I20 -> 4.1637318 | K20: =J20 -> 4.1637318 | L20: n/a | M20: n/a
A21: World | B21: Electricity | C21: Road tax | D21: euro per kWh | E21: {=E19:K19/E20:K20} -> 0.048033834 | F21: 0.048033834 | G21: 0.048033834 | H21: 0.048033834 | I21: 0.048033834 | J21: 0.048033834 | K21: 0.048033834 | L21: n/a | M21: n/a
A22: SE12 | B22: SE12 | C22: Price min | D22: euro per kWh | E22: ='electricity price curves'!B26/1000 -> 0.03445874 | F22: {=E22*POWER(1+$L22,F$1:K$1-$E$1)} -> 0.03445874 | G22: 0.03445874 | H22: 0.03445874 | I22: 0.03445874 | J22: 0.03445874 | K22: 0.03445874 | L22: 0 | M22: https://www.nordpoolgroup.com/Market-data1/Dayahead/Area-Prices/SE/Hourly/?view=table | N22: Nordpool spot prices, min average price per hour, 2021
A23: SE12 | B23: SE12 | C23: Price max | D23: euro per kWh | E23: ='electricity price curves'!B27/1000 -> 0.048860986 | F23: {=E23*POWER(1+$L23,F$1:K$1-$E$1)} -> 0.048860986 | G23: 0.048860986 | H23: 0.048860986 | I23: 0.048860986 | J23: 0.048860986 | K23: 0.048860986 | L23: 0 | M23: https://www.nordpoolgroup.com/Market-data1/Dayahead/Area-Prices/SE/Hourly/?view=table | N23: Nordpool spot prices, max average price per hour, 2021
A24: SE12 | B24: SE12 | C24: CO₂ emissions | D24: kg per kWh | E24: 0.01 | F24: {=E24*POWER(1+$L24,F$1:K$1-$E$1)} -> 0.009039208 | G24: 0.0081707281 | H24: 0.007385691 | I24: 0.0066760797 | J24: 0.0060346473 | K24: 0.0054548432 | L24: -0.02 | M24: n/a | N24: Svensk elproduktion
A25: SE12 | B25: SE12 | C25: CO₂ tax | D25: euro per kWh | E25: {=E24:K24*E8:K8*E7:K7} -> 0.0014 | F25: 0.0015818614 | G25: 0.0017158529 | H25: 0.0018094943 | I25: 0.0018693023 | J25: 0.0019009139 | K25: 0.0019091951 | L25: n/a | M25: n/a
A26: SE34 | B26: SE34 | C26: Price min | D26: euro per kWh | E26: =AVERAGE('electricity price curves'!D26:E26)/1000 -> 0.043459219 | F26: {=E26*POWER(1+$L26,F$1:K$1-$E$1)} -> 0.043459219 | G26: 0.043459219 | H26: 0.043459219 | I26: 0.043459219 | J26: 0.043459219 | K26: 0.043459219 | L26: 0 | M26: https://www.nordpoolgroup.com/Market-data1/Dayahead/Area-Prices/SE/Hourly/?view=table | N26: Nordpool spot prices, min average price per hour, 2021
A27: SE34 | B27: SE34 | C27: Price max | D27: euro per kWh | E27: =AVERAGE('electricity price curves'!D27:E27)/1000 -> 0.097833534 | F27: {=E27*POWER(1+$L27,F$1:K$1-$E$1)} -> 0.097833534 | G27: 0.097833534 | H27: 0.097833534 | I27: 0.097833534 | J27: 0.097833534 | K27: 0.097833534 | L27: 0 | M27: https://www.nordpoolgroup.com/Market-data1/Dayahead/Area-Prices/SE/Hourly/?view=table | N27: Nordpool spot prices, max average price per hour, 2021 | P27: {=E27:K27-E26:K26} -> 0.054374315 | Q27: 0.054374315 | R27: 0.054374315 | S27: 0.054374315 | T27: 0.054374315 | U27: 0.054374315 | V27: 0.054374315
A28: SE34 | B28: SE34 | C28: CO₂ emissions | D28: kg per kWh | E28: 0.09 | F28: {=E28*POWER(1+$L28,F$1:K$1-$E$1)} -> 0.069640284 | G28: 0.053886325 | H28: 0.041696211 | I28: 0.032263733 | J28: 0.024965062 | K28: 0.019317489 | L28: -0.05 | M28: https://naturvardsverket.diva-portal.org/smash/get/diva2:1540012/FULLTEXT01.pdf | N28: Nordisk elmix, approaching current Swedish level of 0.005
A29: SE34 | B29: SE34 | C29: CO₂ tax | D29: euro per kWh | E29: {=E28:K28*E8:K8*E7:K7} -> 0.0126 | F29: 0.01218705 | G29: 0.011316128 | H29: 0.010215572 | I29: 0.0090338452 | J29: 0.0078639944 | K29: 0.0067611211 | L29: n/a | M29: n/a
A30: OtherRegion | B30: OtherRegion | C30: Price min | D30: euro per kWh | E30: ='electricity price curves'!F26/1000 -> 0.071295288 | F30: {=E30*POWER(1+$L30,F$1:K$1-$E$1)} -> 0.071295288 | G30: 0.071295288 | H30: 0.071295288 | I30: 0.071295288 | J30: 0.071295288 | K30: 0.071295288 | L30: 0 | M30: Germany | N30: Nordpool spot prices (DE-LU), min average price per hour, 2021
A31: OtherRegion | B31: OtherRegion | C31: Price max | D31: euro per kWh | E31: ='electricity price curves'!F27/1000 -> 0.1252554 | F31: {=E31*POWER(1+$L31,F$1:K$1-$E$1)} -> 0.1252554 | G31: 0.1252554 | H31: 0.1252554 | I31: 0.1252554 | J31: 0.1252554 | K31: 0.1252554 | L31: 0 | M31: Germany | N31: Nordpool spot prices (DE-LU), max average price per hour, 2021
A32: OtherRegion | B32: OtherRegion | C32: CO₂ emissions | D32: kg per kWh | E32: 0.265 | F32: {=E32*POWER(1+$L32,F$1:K$1-$E$1)} -> 0.1746566 | G32: 0.11511294 | H32: 0.075868812 | I32: 0.050003732 | J32: 0.032956536 | K32: 0.021721044 | L32: -0.08 | M32: EU: https://www.eea.europa.eu/data-and-maps/daviz/co2-emission-intensity-13/#tab-googlechartid_chart_11
A33: OtherRegion | B33: OtherRegion | C33: CO₂ tax | D33: euro per kWh | E33: {=E32:K32*E8:K8*E7:K7} -> 0.0371 | F33: 0.030564906 | G33: 0.024173717 | H33: 0.018587859 | I33: 0.014001045 | J33: 0.010381309 | K33: 0.0076023654 | L33: n/a | M33: n/a
C36: Effective diesel price, incl tax | D36: euro per liter | E36: {=_xlfn.ANCHORARRAY(E15)+_xlfn.ANCHORARRAY(E17)+E18:K18+E19:K19} -> 1.89676 | F36: 2.0382566 | G36: 2.1364471 | H36: 2.1833347 | I36: 2.1551138 | J36: 2.1374986 | K36: 2.1718699
C37: Effective diesel tax ratio | D37: percent | E37: {=(_xlfn.ANCHORARRAY(E17)+E18:K18+E19:K19)/_xlfn.ANCHORARRAY(E36)} -> 0.28825998 | F37: 0.29812269 | G37: 0.29635463 | H37: 0.23738257 | I37: 0.22467884 | J37: 0.24192739 | K37: 0.28558534
C38: Equivalent reduktionsplikt | D38: percent | E38: {=1-_xlfn.ANCHORARRAY(E16)/E13:K13} -> 0.27739938 | F38: 0.33579774 | G38: 0.4379019 | H38: 0.70336687 | I38: 0.83452182 | J38: 0.90129701 | K38: 0.93696048 | N38: =1.64*0.35 -> 0.574
C39: Equivalent diesel emissions | D39: kg CO₂ per kWh | E39: {=_xlfn.ANCHORARRAY(E16)/(vehicles!E106:K106/vehicles!E103:K103)} -> 0.56055484 | F39: 0.51784956 | G39: 0.44045228 | H39: 0.23360916 | I39: 0.13097682 | J39: 0.078517683 | K39: 0.050400352
C40: Electricity vs diesel cost | D40: ratio | E40: {=AVERAGE(E26:E27)*E20:K20/_xlfn.ANCHORARRAY(E15)} -> 0.21789079 | F40: 0.20561395 | G40: 0.19567109 | H40: 0.176663 | I40: 0.17604382 | J40: 0.18153317 | K40: 0.18957823
A42: Backup of values used in RISE REPORT
A43: group | B43: subgroup | C43: variable | D43: unit | E43: 2020 | F43: 2025 | G43: 2030 | H43: 2035 | I43: 2040 | J43: 2045 | K43: 2050 | L43: Annual change | M43: Sources | N43: Comments
...

Sheet powertrains
A1: variable | B1: unit | C1: 2020 | D1: 2025 | E1: 2030 | F1: 2035 | G1: 2040 | H1: 2045 | I1: 2050 | J1: Annual change | K1: Source | W1: Verification of cited source, which I have some doubts about, using estimates by ChatGPT
A2: Cost of replaced ICE powertrain | B2: SEK/truck | C2: 500 | D2: {=C2*POWER(1+$J2,D$1:I$1-$C$1)} -> 525.50503 | E2: 552.31106 | F2: 580.48448 | G2: 610.09502 | H2: 641.216 | I2: 673.92446 | J2: 0.01 | K2: See comment | L2: All values from Trafikverket's 2021 report "Behov av laddinfrastruktur för snabbladdning av tunga fordon längs större vägar", with adjustments by Nils-Gunnar Vågstedt, Scania (spring 2021)
A3: Cost of replaced ICE powertrain | B3: SEK/kW | C3: 650 | D3: {=C3*POWER(1+$J3,D$1:I$1-$C$1)} -> 683.15653 | E3: 718.00438 | F3: 754.62982 | G3: 793.12353 | H3: 833.5808 | I3: 876.10179 | J3: 0.01 | K3: See comment | W3: Power (kW) | X3: 20 ton | Y3: 40 ton | Z3: diff
A4: Cost of new EV powertrain | B4: SEK/truck | C4: 40000 | D4: {=C4*POWER(1+$J4,D$1:I$1-$C$1)} -> 36156.832 | E4: 32682.912 | F4: 29542.764 | G4: 26704.319 | H4: 24138.589 | I4: 21819.373 | J4: -0.02 | K4: See comment | X4: 190 | Y4: 375 | Z4: =Y4-X4 -> 185
A5: Cost of new EV powertrain | B5: SEK/kW | C5: 190 | D5: {=C5*POWER(1+$J5,D$1:I$1-$C$1)} -> 171.74495 | E5: 155.24383 | F5: 140.32813 | G5: 126.84551 | H5: 114.6583 | I5: 103.64202 | J5: -0.02 | K5: See comment
A6: Vehicle OEM markup | B6: % | C6: 1.48 | D6: {=C6*POWER(1+$J6,D$1:I$1-$C$1)} -> 1.48 | E6: 1.48 | F6: 1.48 | G6: 1.48 | H6: 1.48 | I6: 1.48 | J6: 0 | K6: See comment | W6: ICEV components | X6: 20 ton | Y6: 40 ton | Z6: diff | AA6: kg/kW | AB6: intercept
